Workbook

Sheet in
A1: order_id | B1: drink_name | C1: agent | D1: order_sent_back | E1: time_entered | F1: time_ordered | G1: time_making_started | H1: time_completed | I1: time_left
A2: 100001 | B2: Latte | C2: David | D2: 0 | E2: 45931.295 | F2: 45931.295 | G2: 45931.296 | H2: 45931.298 | I2: 45931.304
A3: 100002 | B3: Americano | C3: Eve | D3: 0 | E3: 45931.295 | F3: 45931.295 | G3: 45931.296 | H3: 45931.299 | I3: 45931.307
A4: 100003 | B4: Mocha | C4: David | D4: 0 | E4: 45931.295 | F4: 45931.296 | G4: 45931.296 | H4: 45931.297 | I4: 45931.301
A5: 100004 | B5: Americano | C5: Eve | D5: 0 | E5: 45931.296 | F5: 45931.296 | G5: 45931.296 | H5: 45931.3 | I5: 45931.303
A6: 100005 | B6: Latte | C6: Alice | D6: 0 | E6: 45931.296 | F6: 45931.297 | G6: 45931.297 | H6: 45931.3 | I6: 45931.311
A7: 100006 | B7: Espresso | C7: Eve | D7: 0 | E7: 45931.297 | F7: 45931.298 | G7: 45931.299 | H7: 45931.302 | I7: 45931.31
A8: 100007 | B8: Mocha | C8: Charlie | D8: 0 | E8: 45931.297 | F8: 45931.298 | G8: 45931.3 | H8: 45931.303 | I8: 45931.305
A9: 100008 | B9: Latte | C9: Alice | D9: 0 | E9: 45931.298 | F9: 45931.299 | G9: 45931.3 | H9: 45931.301 | I9: 45931.308
A10: 100009 | B10: Latte | C10: Eve | D10: 0 | E10: 45931.299 | F10: 45931.3 | G10: 45931.301 | H10: 45931.303 | I10: 45931.309
A11: 100010 | B11: Espresso | C11: Alice | D11: 0 | E11: 45931.3 | F11: 45931.301 | G11: 45931.301 | H11: 45931.304 | I11: 45931.314
A12: 100011 | B12: Latte | C12: Alice | D12: 0 | E12: 45931.301 | F12: 45931.302 | G12: 45931.302 | H12: 45931.303 | I12: 45931.304
A13: 100012 | B13: Espresso | C13: Bob | D13: 0 | E13: 45931.302 | F13: 45931.303 | G13: 45931.303 | H13: 45931.305 | I13: 45931.313
... A10001: 110000 | B10001: Americano | C10001: Alice | D10001: 0 | E10001: 45958.708 | F10001: 45958.709 | G10001: 45958.709 | H10001: 45958.71 | I10001: 45958.718

Sheet calc
A1: order_id | B1: drink | C1: agent | D1: wait_min | E1: queue_min | F1: make_min | G1: sit_min | H1: total_min | I1: hour
A2: =in!A2 -> 100001 | B2: =in!B2 -> Latte | C2: =in!C2 -> David | D2: =(in!F2-in!E2)*1440 -> 1.2 | E2: =(in!G2-in!F2)*1440 -> 1 | F2: =(in!H2-in!G2)*1440 -> 2.5333333 | G2: =(in!I2-in!H2)*1440 -> 9.35 | H2: =(in!I2-in!E2)*1440 -> 14.083333 | I2: =HOUR(in!E2) -> 7
A3: =in!A3 -> 100002 | B3: =in!B3 -> Americano | C3: =in!C3 -> Eve | D3: =(in!F3-in!E3)*1440 -> 0.53333333 | E3: =(in!G3-in!F3)*1440 -> 0.73333334 | F3: =(in!H3-in!G3)*1440 -> 4.8666667 | G3: =(in!I3-in!H3)*1440 -> 11.65 | H3: =(in!I3-in!E3)*1440 -> 17.783333 | I3: =HOUR(in!E3) -> 7
A4: =in!A4 -> 100003 | B4: =in!B4 -> Mocha | C4: =in!C4 -> David | D4: =(in!F4-in!E4)*1440 -> 1.1 | E4: =(in!G4-in!F4)*1440 -> 0.93333333 | F4: =(in!H4-in!G4)*1440 -> 1.5333333 | G4: =(in!I4-in!H4)*1440 -> 4.7333333 | H4: =(in!I4-in!E4)*1440 -> 8.3 | I4: =HOUR(in!E4) -> 7
A5: =in!A5 -> 100004 | B5: =in!B5 -> Americano | C5: =in!C5 -> Eve | D5: =(in!F5-in!E5)*1440 -> 0.54999999 | E5: =(in!G5-in!F5)*1440 -> 0.35 | F5: =(in!H5-in!G5)*1440 -> 4.9166667 | G5: =(in!I5-in!H5)*1440 -> 4.4833333 | H5: =(in!I5-in!E5)*1440 -> 10.3 | I5: =HOUR(in!E5) -> 7
A6: =in!A6 -> 100005 | B6: =in!B6 -> Latte | C6: =in!C6 -> Alice | D6: =(in!F6-in!E6)*1440 -> 1.3166667 | E6: =(in!G6-in!F6)*1440 -> 0.55 | F6: =(in!H6-in!G6)*1440 -> 4.4833333 | G6: =(in!I6-in!H6)*1440 -> 15.85 | H6: =(in!I6-in!E6)*1440 -> 22.2 | I6: =HOUR(in!E6) -> 7
A7: =in!A7 -> 100006 | B7: =in!B7 -> Espresso | C7: =in!C7 -> Eve | D7: =(in!F7-in!E7)*1440 -> 1.75 | E7: =(in!G7-in!F7)*1440 -> 1.2833333 | F7: =(in!H7-in!G7)*1440 -> 4.7 | G7: =(in!I7-in!H7)*1440 -> 11.283333 | H7: =(in!I7-in!E7)*1440 -> 19.016667 | I7: =HOUR(in!E7) -> 7
A8: =in!A8 -> 100007 | B8: =in!B8 -> Mocha | C8: =in!C8 -> Charlie | D8: =(in!F8-in!E8)*1440 -> 1.4666667 | E8: =(in!G8-in!F8)*1440 -> 2.1166667 | F8: =(in!H8-in!G8)*1440 -> 5.35 | G8: =(in!I8-in!H8)*1440 -> 1.6333333 | H8: =(in!I8-in!E8)*1440 -> 10.566667 | I8: =HOUR(in!E8) -> 7
A9: =in!A9 -> 100008 | B9: =in!B9 -> Latte | C9: =in!C9 -> Alice | D9: =(in!F9-in!E9)*1440 -> 1.2833333 | E9: =(in!G9-in!F9)*1440 -> 1.35 | F9: =(in!H9-in!G9)*1440 -> 1.2166667 | G9: =(in!I9-in!H9)*1440 -> 10.55 | H9: =(in!I9-in!E9)*1440 -> 14.4 | I9: =HOUR(in!E9) -> 7
A10: =in!A10 -> 100009 | B10: =in!B10 -> Latte | C10: =in!C10 -> Eve | D10: =(in!F10-in!E10)*1440 -> 1.7 | E10: =(in!G10-in!F10)*1440 -> 1.1666667 | F10: =(in!H10-in!G10)*1440 -> 3.9 | G10: =(in!I10-in!H10)*1440 -> 8.4 | H10: =(in!I10-in!E10)*1440 -> 15.166667 | I10: =HOUR(in!E10) -> 7
A11: =in!A11 -> 100010 | B11: =in!B11 -> Espresso | C11: =in!C11 -> Alice | D11: =(in!F11-in!E11)*1440 -> 1.2166667 | E11: =(in!G11-in!F11)*1440 -> 0.73333333 | F11: =(in!H11-in!G11)*1440 -> 4.0833333 | G11: =(in!I11-in!H11)*1440 -> 13.716667 | H11: =(in!I11-in!E11)*1440 -> 19.75 | I11: =HOUR(in!E11) -> 7
A12: =in!A12 -> 100011 | B12: =in!B12 -> Latte | C12: =in!C12 -> Alice | D12: =(in!F12-in!E12)*1440 -> 1.4666667 | E12: =(in!G12-in!F12)*1440 -> 0.11666667 | F12: =(in!H12-in!G12)*1440 -> 1 | G12: =(in!I12-in!H12)*1440 -> 1.4833333 | H12: =(in!I12-in!E12)*1440 -> 4.0666667 | I12: =HOUR(in!E12) -> 7
A13: =in!A13 -> 100012 | B13: =in!B13 -> Espresso | C13: =in!C13 -> Bob | D13: =(in!F13-in!E13)*1440 -> 1.9666667 | E13: =(in!G13-in!F13)*1440 -> 0.58333333 | F13: =(in!H13-in!G13)*1440 -> 1.85 | G13: =(in!I13-in!H13)*1440 -> 11.933333 | H13: =(in!I13-in!E13)*1440 -> 16.333333 | I13: =HOUR(in!E13) -> 7
... A10001: =in!A10001 -> 110000 | B10001: =in!B10001 -> Americano | C10001: =in!C10001 -> Alice | D10001: =(in!F10001-in!E10001)*1440 -> 0.9 | E10001: =(in!G10001-in!F10001)*1440 -> 0.48333333 | F10001: =(in!H10001-in!G10001)*1440 -> 1.4833333 | G10001: =(in!I10001-in!H10001)*1440 -> 12.05 | H10001: =(in!I10001-in!E10001)*1440 -> 14.916667 | I10001: =HOUR(in!E10001) -> 16

Sheet Stage Summary
A1: Stage Summary — durations in minutes (n = 10,000 orders)
A3: Statistic | B3: wait_min | C3: queue_min | D3: make_min | E3: sit_min | F3: total_min
A4: Count | B4: =COUNT(calc!D2:D10001) -> 10000 | C4: =COUNT(calc!E2:E10001) -> 10000 | D4: =COUNT(calc!F2:F10001) -> 10000 | E4: =COUNT(calc!G2:G10001) -> 10000 | F4: =COUNT(calc!H2:H10001) -> 10000
A5: Mean | B5: =AVERAGE(calc!D2:D10001) -> 1.243345 | C5: =AVERAGE(calc!E2:E10001) -> 0.97500167 | D5: =AVERAGE(calc!F2:F10001) -> 3.2450583 | E5: =AVERAGE(calc!G2:G10001) -> 10.186608 | F5: =AVERAGE(calc!H2:H10001) -> 15.650013
A6: Median (p50) | B6: =MEDIAN(calc!D2:D10001) -> 1.2333333 | C6: =MEDIAN(calc!E2:E10001) -> 0.9 | D6: =MEDIAN(calc!F2:F10001) -> 3.1833333 | E6: =MEDIAN(calc!G2:G10001) -> 10.316667 | F6: =MEDIAN(calc!H2:H10001) -> 15.733333
A7: StdDev | B7: =_xlfn.STDEV.S(calc!D2:D10001) -> 0.42959784 | C7: =_xlfn.STDEV.S(calc!E2:E10001) -> 0.6283823 | D7: =_xlfn.STDEV.S(calc!F2:F10001) -> 1.4314321 | E7: =_xlfn.STDEV.S(calc!G2:G10001) -> 5.7030391 | F7: =_xlfn.STDEV.S(calc!H2:H10001) -> 5.987652
A8: Min | B8: =MIN(calc!D2:D10001) -> 0.49999999 | C8: =MIN(calc!E2:E10001) -> 0.083333332 | D8: =MIN(calc!F2:F10001) -> 0.75 | E8: =MIN(calc!G2:G10001) -> 0.25 | F8: =MIN(calc!H2:H10001) -> 2.5
A9: p25 | B9: =_xlfn.PERCENTILE.INC(calc!D2:D10001,0.25) -> 0.88333333 | C9: =_xlfn.PERCENTILE.INC(calc!E2:E10001,0.25) -> 0.5 | D9: =_xlfn.PERCENTILE.INC(calc!F2:F10001,0.25) -> 2.0791667 | E9: =_xlfn.PERCENTILE.INC(calc!G2:G10001,0.25) -> 5.2666667 | F9: =_xlfn.PERCENTILE.INC(calc!H2:H10001,0.25) -> 10.683333
A10: p75 | B10: =_xlfn.PERCENTILE.INC(calc!D2:D10001,0.75) -> 1.6166667 | C10: =_xlfn.PERCENTILE.INC(calc!E2:E10001,0.75) -> 1.2833333 | D10: =_xlfn.PERCENTILE.INC(calc!F2:F10001,0.75) -> 4.2333333 | E10: =_xlfn.PERCENTILE.INC(calc!G2:G10001,0.75) -> 15.1 | F10: =_xlfn.PERCENTILE.INC(calc!H2:H10001,0.75) -> 20.633333
A11: p90 | B11: =_xlfn.PERCENTILE.INC(calc!D2:D10001,0.9) -> 1.835 | C11: =_xlfn.PERCENTILE.INC(calc!E2:E10001,0.9) -> 1.7666667 | D11: =_xlfn.PERCENTILE.INC(calc!F2:F10001,0.9) -> 4.9166667 | E11: =_xlfn.PERCENTILE.INC(calc!G2:G10001,0.9) -> 18.033333 | F11: =_xlfn.PERCENTILE.INC(calc!H2:H10001,0.9) -> 23.55
A12: p99 | B12: =_xlfn.PERCENTILE.INC(calc!D2:D10001,0.99) -> 1.9833333 | C12: =_xlfn.PERCENTILE.INC(calc!E2:E10001,0.99) -> 2.8668333 | D12: =_xlfn.PERCENTILE.INC(calc!F2:F10001,0.99) -> 7.1666667 | E12: =_xlfn.PERCENTILE.INC(calc!G2:G10001,0.99) -> 19.766667 | F12: =_xlfn.PERCENTILE.INC(calc!H2:H10001,0.99) -> 27.467
A13: Max | B13: =MAX(calc!D2:D10001) -> 1.9833333 | C13: =MAX(calc!E2:E10001) -> 2.9833333 | D13: =MAX(calc!F2:F10001) -> 7.4833333 | E13: =MAX(calc!G2:G10001) -> 19.983333 | F13: =MAX(calc!H2:H10001) -> 30.833333
A14: IQR (p75 − p25) | B14: =B10-B9 -> 0.73333334 | C14: =C10-C9 -> 0.78333333 | D14: =D10-D9 -> 2.1541667 | E14: =E10-E9 -> 9.8333333 | F14: =F10-F9 -> 9.95
A15: CV (std/mean) | B15: =B7/B5 -> 0.34551781 | C15: =C7/C5 -> 0.64449357 | D15: =D7/D5 -> 0.44111137 | E15: =E7/E5 -> 0.55985652 | F15: =F7/F5 -> 0.38259724
A17: Reading the table
A18: Mean ≫ Median ⇒ right-skewed (long tail). CV > 50% ⇒ high variability relative to typical value.

Sheet By Agent
A1: By Agent — make_min statistics (minutes)
A3: Agent | B3: Count | C3: Mean | D3: Median | E3: StdDev | F3: p25 | G3: p75 | H3: p90 | I3: Min | J3: Max
A4: Alice | B4: =COUNTIF(calc!$C$2:$C$10001,A4) -> 2503 | C4: =AVERAGEIF(calc!$C$2:$C$10001,A4,calc!$F$2:$F$10001) -> 2.9998801 | D4: {=_xlfn.PERCENTILE.INC(IF(calc!$C$2:$C$10001=A4,calc!$F$2:$F$10001),0.5)} -> 3 | E4: {=_xlfn.STDEV.S(IF(calc!$C$2:$C$10001=A4,calc!$F$2:$F$10001))} -> 1.1433634 | F4: {=_xlfn.PERCENTILE.INC(IF(calc!$C$2:$C$10001=A4,calc!$F$2:$F$10001),0.25)} -> 2.0333333 | G4: {=_xlfn.PERCENTILE.INC(IF(calc!$C$2:$C$10001=A4,calc!$F$2:$F$10001),0.75)} -> 3.9666667 | H4: {=_xlfn.PERCENTILE.INC(IF(calc!$C$2:$C$10001=A4,calc!$F$2:$F$10001),0.9)} -> 4.6 | I4: =_xlfn.MINIFS(calc!$F$2:$F$10001,calc!$C$2:$C$10001,A4) -> 0.99999999 | J4: =_xlfn.MAXIFS(calc!$F$2:$F$10001,calc!$C$2:$C$10001,A4) -> 4.9833333
A5: Bob | B5: =COUNTIF(calc!$C$2:$C$10001,A5) -> 2456 | C5: =AVERAGEIF(calc!$C$2:$C$10001,A5,calc!$F$2:$F$10001) -> 3.0045128 | D5: {=_xlfn.PERCENTILE.INC(IF(calc!$C$2:$C$10001=A5,calc!$F$2:$F$10001),0.5)} -> 3.0333333 | E5: {=_xlfn.STDEV.S(IF(calc!$C$2:$C$10001=A5,calc!$F$2:$F$10001))} -> 1.1483904 | F5: {=_xlfn.PERCENTILE.INC(IF(calc!$C$2:$C$10001=A5,calc!$F$2:$F$10001),0.25)} -> 2.0166667 | G5: {=_xlfn.PERCENTILE.INC(IF(calc!$C$2:$C$10001=A5,calc!$F$2:$F$10001),0.75)} -> 4 | H5: {=_xlfn.PERCENTILE.INC(IF(calc!$C$2:$C$10001=A5,calc!$F$2:$F$10001),0.9)} -> 4.6 | I5: =_xlfn.MINIFS(calc!$F$2:$F$10001,calc!$C$2:$C$10001,A5) -> 0.99999999 | J5: =_xlfn.MAXIFS(calc!$F$2:$F$10001,calc!$C$2:$C$10001,A5) -> 4.9833333
A6: Charlie | B6: =COUNTIF(calc!$C$2:$C$10001,A6) -> 2002 | C6: =AVERAGEIF(calc!$C$2:$C$10001,A6,calc!$F$2:$F$10001) -> 4.1770813 | D6: {=_xlfn.PERCENTILE.INC(IF(calc!$C$2:$C$10001=A6,calc!$F$2:$F$10001),0.5)} -> 4.2166667 | E6: {=_xlfn.STDEV.S(IF(calc!$C$2:$C$10001=A6,calc!$F$2:$F$10001))} -> 1.9694508 | F6: {=_xlfn.PERCENTILE.INC(IF(calc!$C$2:$C$10001=A6,calc!$F$2:$F$10001),0.25)} -> 2.4666667 | G6: {=_xlfn.PERCENTILE.INC(IF(calc!$C$2:$C$10001=A6,calc!$F$2:$F$10001),0.75)} -> 5.9166667 | H6: {=_xlfn.PERCENTILE.INC(IF(calc!$C$2:$C$10001=A6,calc!$F$2:$F$10001),0.9)} -> 6.8333333 | I6: =_xlfn.MINIFS(calc!$F$2:$F$10001,calc!$C$2:$C$10001,A6) -> 0.75 | J6: =_xlfn.MAXIFS(calc!$F$2:$F$10001,calc!$C$2:$C$10001,A6) -> 7.4833333
A7: David | B7: =COUNTIF(calc!$C$2:$C$10001,A7) -> 1514 | C7: =AVERAGEIF(calc!$C$2:$C$10001,A7,calc!$F$2:$F$10001) -> 3.0271026 | D7: {=_xlfn.PERCENTILE.INC(IF(calc!$C$2:$C$10001=A7,calc!$F$2:$F$10001),0.5)} -> 3.0833333 | E7: {=_xlfn.STDEV.S(IF(calc!$C$2:$C$10001=A7,calc!$F$2:$F$10001))} -> 1.1538157 | F7: {=_xlfn.PERCENTILE.INC(IF(calc!$C$2:$C$10001=A7,calc!$F$2:$F$10001),0.25)} -> 1.9875 | G7: {=_xlfn.PERCENTILE.INC(IF(calc!$C$2:$C$10001=A7,calc!$F$2:$F$10001),0.75)} -> 4.0166667 | H7: {=_xlfn.PERCENTILE.INC(IF(calc!$C$2:$C$10001=A7,calc!$F$2:$F$10001),0.9)} -> 4.5666667 | I7: =_xlfn.MINIFS(calc!$F$2:$F$10001,calc!$C$2:$C$10001,A7) -> 0.99999999 | J7: =_xlfn.MAXIFS(calc!$F$2:$F$10001,calc!$C$2:$C$10001,A7) -> 4.9833333
A8: Eve | B8: =COUNTIF(calc!$C$2:$C$10001,A8) -> 1525 | C8: =AVERAGEIF(calc!$C$2:$C$10001,A8,calc!$F$2:$F$10001) -> 3.0277049 | D8: {=_xlfn.PERCENTILE.INC(IF(calc!$C$2:$C$10001=A8,calc!$F$2:$F$10001),0.5)} -> 3.0833333 | E8: {=_xlfn.STDEV.S(IF(calc!$C$2:$C$10001=A8,calc!$F$2:$F$10001))} -> 1.1536367 | F8: {=_xlfn.PERCENTILE.INC(IF(calc!$C$2:$C$10001=A8,calc!$F$2:$F$10001),0.25)} -> 2.0166667 | G8: {=_xlfn.PERCENTILE.INC(IF(calc!$C$2:$C$10001=A8,calc!$F$2:$F$10001),0.75)} -> 4.05 | H8: {=_xlfn.PERCENTILE.INC(IF(calc!$C$2:$C$10001=A8,calc!$F$2:$F$10001),0.9)} -> 4.6166667 | I8: =_xlfn.MINIFS(calc!$F$2:$F$10001,calc!$C$2:$C$10001,A8) -> 0.99999999 | J8: =_xlfn.MAXIFS(calc!$F$2:$F$10001,calc!$C$2:$C$10001,A8) -> 4.9833333
A9: OVERALL | B9: =COUNTA(calc!$C$2:$C$10001) -> 10000 | C9: =AVERAGE(calc!$F$2:$F$10001) -> 3.2450583 | D9: =MEDIAN(calc!$F$2:$F$10001) -> 3.1833333 | E9: =_xlfn.STDEV.S(calc!$F$2:$F$10001) -> 1.4314321 | F9: =_xlfn.PERCENTILE.INC(calc!$F$2:$F$10001,0.25) -> 2.0791667 | G9: =_xlfn.PERCENTILE.INC(calc!$F$2:$F$10001,0.75) -> 4.2333333 | H9: =_xlfn.PERCENTILE.INC(calc!$F$2:$F$10001,0.9) -> 4.9166667 | I9: =MIN(calc!$F$2:$F$10001) -> 0.75 | J9: =MAX(calc!$F$2:$F$10001) -> 7.4833333
A11: One-way ANOVA: does mean make_min differ by agent?
A13: Grand mean | B13: =C9 -> 3.2450583
A14: k (groups) | B14: 5
A15: N (total) | B15: =SUM(B4:B8) -> 10000
A16: SS Between | B16: {=SUMPRODUCT(B4:B8,(C4:C8-B13)^2)} -> 2175.6084
A17: SS Within | B17: {=SUMPRODUCT(B4:B8-1,E4:E8^2)} -> 18312.322
A18: df Between | B18: =B14-1 -> 4
A19: df Within | B19: =B15-B14 -> 9995
A20: MS Between | B20: =B16/B18 -> 543.9021
A21: MS Within | B21: =B17/B19 -> 1.8321482
A22: F statistic | B22: =B20/B21 -> 296.86578
A23: p-value | B23: =_xlfn.F.DIST.RT(B22,B18,B19) -> 1.1862143e-241
A24: Interpretation | B24: =IF(B23<0.05,"Reject H0: at least one agent's mean differs significantly","No significant difference between agents") -> Reject H0: at least one agent's mean differs significantly
A26: Tukey HSD pairwise comparisons (make_min, α=0.05)
A27: MSW | B27: =B21 -> 1.8321482 | C27: df within | D27: =B19 -> 9995 | E27: q crit (α=0.05, k=5) | F27: 3.8578
A29: Group A | B29: Group B | C29: Mean diff (A−B) | D29: SE | E29: q statistic | F29: p-value | G29: 95% CI low | H29: 95% CI high | I29: Significant?
A30: Alice | B30: Bob | C30: =C4-C5 -> -0.004632614 | D30: =SQRT($B$27*(1/B4+1/B5)/2) -> 0.027184275 | E30: =ABS(C30)/D30 -> 0.17041521 | F30: =1-_xlfn.F.DIST(E30^2/2,1,$D$27,TRUE) -> 0.90408811 | G30: =C30-$F$27*D30 -> -0.10950411 | H30: =C30+$F$27*D30 -> 0.10023888 | I30: =IF(E30>$F$27,"YES","no") -> no
A31: Alice | B31: Charlie | C31: =C4-C6 -> -1.1772011 | D31: =SQRT($B$27*(1/B4+1/B6)/2) -> 0.028697908 | E31: =ABS(C31)/D31 -> 41.02045 | F31: =1-_xlfn.F.DIST(E31^2/2,1,$D$27,TRUE) -> 0 | G31: =C31-$F$27*D31 -> -1.2879119 | H31: =C31+$F$27*D31 -> -1.0664903 | I31: =IF(E31>$F$27,"YES","no") -> YES
A32: Alice | B32: David | C32: =C4-C7 -> -0.027222454 | D32: =SQRT($B$27*(1/B4+1/B7)/2) -> 0.031161823 | E32: =ABS(C32)/D32 -> 0.87358349 | F32: =1-_xlfn.F.DIST(E32^2/2,1,$D$27,TRUE) -> 0.5367761 | G32: =C32-$F$27*D32 -> -0.14743854 | H32: =C32+$F$27*D32 -> 0.092993627 | I32: =IF(E32>$F$27,"YES","no") -> no
A33: Alice | B33: Eve | C33: =C4-C8 -> -0.027824774 | D33: =SQRT($B$27*(1/B4+1/B8)/2) -> 0.031091716 | E33: =ABS(C33)/D33 -> 0.89492565 | F33: =1-_xlfn.F.DIST(E33^2/2,1,$D$27,TRUE) -> 0.52687351 | G33: =C33-$F$27*D33 -> -0.1477704 | H33: =C33+$F$27*D33 -> 0.092120847 | I33: =IF(E33>$F$27,"YES","no") -> no
A34: Bob | B34: Charlie | C34: =C5-C6 -> -1.1725685 | D34: =SQRT($B$27*(1/B5+1/B6)/2) -> 0.028819678 | E34: =ABS(C34)/D34 -> 40.686385 | F34: =1-_xlfn.F.DIST(E34^2/2,1,$D$27,TRUE) -> 0 | G34: =C34-$F$27*D34 -> -1.283749 | H34: =C34+$F$27*D34 -> -1.0613879 | I34: =IF(E34>$F$27,"YES","no") -> YES
A35: Bob | B35: David | C35: =C5-C7 -> -0.02258984 | D35: =SQRT($B$27*(1/B5+1/B7)/2) -> 0.031274001 | E35: =ABS(C35)/D35 -> 0.72232013 | F35: =1-_xlfn.F.DIST(E35^2/2,1,$D$27,TRUE) -> 0.60953218 | G35: =C35-$F$27*D35 -> -0.14323868 | H35: =C35+$F$27*D35 -> 0.098058999 | I35: =IF(E35>$F$27,"YES","no") -> no
A36: Bob | B36: Eve | C36: =C5-C8 -> -0.02319216 | D36: =SQRT($B$27*(1/B5+1/B8)/2) -> 0.031204145 | E36: =ABS(C36)/D36 -> 0.74323972 | F36: =1-_xlfn.F.DIST(E36^2/2,1,$D$27,TRUE) -> 0.59921267 | G36: =C36-$F$27*D36 -> -0.14357151 | H36: =C36+$F$27*D36 -> 0.097187192 | I36: =IF(E36>$F$27,"YES","no") -> no
A37: Charlie | B37: David | C37: =C6-C7 -> 1.1499787 | D37: =SQRT($B$27*(1/B6+1/B7)/2) -> 0.032598286 | E37: =ABS(C37)/D37 -> 35.277274 | F37: =1-_xlfn.F.DIST(E37^2/2,1,$D$27,TRUE) -> 0 | G37: =C37-$F$27*D37 -> 1.024221 | H37: =C37+$F$27*D37 -> 1.2757363 | I37: =IF(E37>$F$27,"YES","no") -> YES
A38: Charlie | B38: Eve | C38: =C6-C8 -> 1.1493763 | D38: =SQRT($B$27*(1/B6+1/B8)/2) -> 0.032531274 | E38: =ABS(C38)/D38 -> 35.331427 | F38: =1-_xlfn.F.DIST(E38^2/2,1,$D$27,TRUE) -> 0 | G38: =C38-$F$27*D38 -> 1.0238772 | H38: =C38+$F$27*D38 -> 1.2748755 | I38: =IF(E38>$F$27,"YES","no") -> YES
A39: David | B39: Eve | C39: =C7-C8 -> -0.00060231994 | D39: =SQRT($B$27*(1/B7+1/B8)/2) -> 0.034724244 | E39: =ABS(C39)/D39 -> 0.017345804 | F39: =1-_xlfn.F.DIST(E39^2/2,1,$D$27,TRUE) -> 0.99021417 | G39: =C39-$F$27*D39 -> -0.13456151 | H39: =C39+$F$27*D39 -> 0.13335687 | I39: =IF(E39>$F$27,"YES","no") -> no
A41: Bottom line | B41: Charlie is significantly slower than every other agent (~1.15–1.18 min). All other pairs (Alice/Bob/David/Eve) are statistically indistinguishable.

Sheet By Drink
A1: By Drink — make_min statistics (minutes)
A3: Drink | B3: Count | C3: Mean | D3: Median | E3: StdDev | F3: p25 | G3: p75 | H3: p90 | I3: Min | J3: Max
A4: Espresso | B4: =COUNTIF(calc!$B$2:$B$10001,A4) -> 1031 | C4: =AVERAGEIF(calc!$B$2:$B$10001,A4,calc!$F$2:$F$10001) -> 3.2871807 | D4: {=_xlfn.PERCENTILE.INC(IF(calc!$B$2:$B$10001=A4,calc!$F$2:$F$10001),0.5)} -> 3.1666667 | E4: {=_xlfn.STDEV.S(IF(calc!$B$2:$B$10001=A4,calc!$F$2:$F$10001))} -> 1.4423225 | F4: {=_xlfn.PERCENTILE.INC(IF(calc!$B$2:$B$10001=A4,calc!$F$2:$F$10001),0.25)} -> 2.1333333 | G4: {=_xlfn.PERCENTILE.INC(IF(calc!$B$2:$B$10001=A4,calc!$F$2:$F$10001),0.75)} -> 4.225 | H4: {=_xlfn.PERCENTILE.INC(IF(calc!$B$2:$B$10001=A4,calc!$F$2:$F$10001),0.9)} -> 4.95 | I4: =_xlfn.MINIFS(calc!$F$2:$F$10001,calc!$B$2:$B$10001,A4) -> 0.75000001 | J4: =_xlfn.MAXIFS(calc!$F$2:$F$10001,calc!$B$2:$B$10001,A4) -> 7.4666667
A5: Americano | B5: =COUNTIF(calc!$B$2:$B$10001,A5) -> 978 | C5: =AVERAGEIF(calc!$B$2:$B$10001,A5,calc!$F$2:$F$10001) -> 3.2125937 | D5: {=_xlfn.PERCENTILE.INC(IF(calc!$B$2:$B$10001=A5,calc!$F$2:$F$10001),0.5)} -> 3.1166667 | E5: {=_xlfn.STDEV.S(IF(calc!$B$2:$B$10001=A5,calc!$F$2:$F$10001))} -> 1.4358452 | F5: {=_xlfn.PERCENTILE.INC(IF(calc!$B$2:$B$10001=A5,calc!$F$2:$F$10001),0.25)} -> 2.0333333 | G5: {=_xlfn.PERCENTILE.INC(IF(calc!$B$2:$B$10001=A5,calc!$F$2:$F$10001),0.75)} -> 4.2125 | H5: {=_xlfn.PERCENTILE.INC(IF(calc!$B$2:$B$10001=A5,calc!$F$2:$F$10001),0.9)} -> 4.9166667 | I5: =_xlfn.MINIFS(calc!$F$2:$F$10001,calc!$B$2:$B$10001,A5) -> 0.78333333 | J5: =_xlfn.MAXIFS(calc!$F$2:$F$10001,calc!$B$2:$B$10001,A5) -> 7.4833333
A6: Latte | B6: =COUNTIF(calc!$B$2:$B$10001,A6) -> 2481 | C6: =AVERAGEIF(calc!$B$2:$B$10001,A6,calc!$F$2:$F$10001) -> 3.2045949 | D6: {=_xlfn.PERCENTILE.INC(IF(calc!$B$2:$B$10001=A6,calc!$F$2:$F$10001),0.5)} -> 3.15 | E6: {=_xlfn.STDEV.S(IF(calc!$B$2:$B$10001=A6,calc!$F$2:$F$10001))} -> 1.4070117 | F6: {=_xlfn.PERCENTILE.INC(IF(calc!$B$2:$B$10001=A6,calc!$F$2:$F$10001),0.25)} -> 2.0666667 | G6: {=_xlfn.PERCENTILE.INC(IF(calc!$B$2:$B$10001=A6,calc!$F$2:$F$10001),0.75)} -> 4.2 | H6: {=_xlfn.PERCENTILE.INC(IF(calc!$B$2:$B$10001=A6,calc!$F$2:$F$10001),0.9)} -> 4.8666667 | I6: =_xlfn.MINIFS(calc!$F$2:$F$10001,calc!$B$2:$B$10001,A6) -> 0.75 | J6: =_xlfn.MAXIFS(calc!$F$2:$F$10001,calc!$B$2:$B$10001,A6) -> 7.4666667
A7: Cappuccino | B7: =COUNTIF(calc!$B$2:$B$10001,A7) -> 1466 | C7: =AVERAGEIF(calc!$B$2:$B$10001,A7,calc!$F$2:$F$10001) -> 3.2376648 | D7: {=_xlfn.PERCENTILE.INC(IF(calc!$B$2:$B$10001=A7,calc!$F$2:$F$10001),0.5)} -> 3.2 | E7: {=_xlfn.STDEV.S(IF(calc!$B$2:$B$10001=A7,calc!$F$2:$F$10001))} -> 1.4320941 | F7: {=_xlfn.PERCENTILE.INC(IF(calc!$B$2:$B$10001=A7,calc!$F$2:$F$10001),0.25)} -> 2.0333333 | G7: {=_xlfn.PERCENTILE.INC(IF(calc!$B$2:$B$10001=A7,calc!$F$2:$F$10001),0.75)} -> 4.25 | H7: {=_xlfn.PERCENTILE.INC(IF(calc!$B$2:$B$10001=A7,calc!$F$2:$F$10001),0.9)} -> 4.9 | I7: =_xlfn.MINIFS(calc!$F$2:$F$10001,calc!$B$2:$B$10001,A7) -> 0.75 | J7: =_xlfn.MAXIFS(calc!$F$2:$F$10001,calc!$B$2:$B$10001,A7) -> 7.4833333
A8: Mocha | B8: =COUNTIF(calc!$B$2:$B$10001,A8) -> 804 | C8: =AVERAGEIF(calc!$B$2:$B$10001,A8,calc!$F$2:$F$10001) -> 3.2988391 | D8: {=_xlfn.PERCENTILE.INC(IF(calc!$B$2:$B$10001=A8,calc!$F$2:$F$10001),0.5)} -> 3.2583333 | E8: {=_xlfn.STDEV.S(IF(calc!$B$2:$B$10001=A8,calc!$F$2:$F$10001))} -> 1.4851973 | F8: {=_xlfn.PERCENTILE.INC(IF(calc!$B$2:$B$10001=A8,calc!$F$2:$F$10001),0.25)} -> 2.05 | G8: {=_xlfn.PERCENTILE.INC(IF(calc!$B$2:$B$10001=A8,calc!$F$2:$F$10001),0.75)} -> 4.2708333 | H8: {=_xlfn.PERCENTILE.INC(IF(calc!$B$2:$B$10001=A8,calc!$F$2:$F$10001),0.9)} -> 4.9166667 | I8: =_xlfn.MINIFS(calc!$F$2:$F$10001,calc!$B$2:$B$10001,A8) -> 0.8 | J8: =_xlfn.MAXIFS(calc!$F$2:$F$10001,calc!$B$2:$B$10001,A8) -> 7.4666667
A9: Tea | B9: =COUNTIF(calc!$B$2:$B$10001,A9) -> 616 | C9: =AVERAGEIF(calc!$B$2:$B$10001,A9,calc!$F$2:$F$10001) -> 3.21296 | D9: {=_xlfn.PERCENTILE.INC(IF(calc!$B$2:$B$10001=A9,calc!$F$2:$F$10001),0.5)} -> 3.1333333 | E9: {=_xlfn.STDEV.S(IF(calc!$B$2:$B$10001=A9,calc!$F$2:$F$10001))} -> 1.4698027 | F9: {=_xlfn.PERCENTILE.INC(IF(calc!$B$2:$B$10001=A9,calc!$F$2:$F$10001),0.25)} -> 2.0166667 | G9: {=_xlfn.PERCENTILE.INC(IF(calc!$B$2:$B$10001=A9,calc!$F$2:$F$10001),0.75)} -> 4.0916667 | H9: {=_xlfn.PERCENTILE.INC(IF(calc!$B$2:$B$10001=A9,calc!$F$2:$F$10001),0.9)} -> 4.9583333 | I9: =_xlfn.MINIFS(calc!$F$2:$F$10001,calc!$B$2:$B$10001,A9) -> 0.75 | J9: =_xlfn.MAXIFS(calc!$F$2:$F$10001,calc!$B$2:$B$10001,A9) -> 7.35
A10: Flat White | B10: =COUNTIF(calc!$B$2:$B$10001,A10) -> 716 | C10: =AVERAGEIF(calc!$B$2:$B$10001,A10,calc!$F$2:$F$10001) -> 3.2560521 | D10: {=_xlfn.PERCENTILE.INC(IF(calc!$B$2:$B$10001=A10,calc!$F$2:$F$10001),0.5)} -> 3.2333333 | E10: {=_xlfn.STDEV.S(IF(calc!$B$2:$B$10001=A10,calc!$F$2:$F$10001))} -> 1.4109902 | F10: {=_xlfn.PERCENTILE.INC(IF(calc!$B$2:$B$10001=A10,calc!$F$2:$F$10001),0.25)} -> 2.0458333 | G10: {=_xlfn.PERCENTILE.INC(IF(calc!$B$2:$B$10001=A10,calc!$F$2:$F$10001),0.75)} -> 4.2 | H10: {=_xlfn.PERCENTILE.INC(IF(calc!$B$2:$B$10001=A10,calc!$F$2:$F$10001),0.9)} -> 4.8416667 | I10: =_xlfn.MINIFS(calc!$F$2:$F$10001,calc!$B$2:$B$10001,A10) -> 0.81666667 | J10: =_xlfn.MAXIFS(calc!$F$2:$F$10001,calc!$B$2:$B$10001,A10) -> 7.4833333
A11: Cold Brew | B11: =COUNTIF(calc!$B$2:$B$10001,A11) -> 980 | C11: =AVERAGEIF(calc!$B$2:$B$10001,A11,calc!$F$2:$F$10001) -> 3.2615986 | D11: {=_xlfn.PERCENTILE.INC(IF(calc!$B$2:$B$10001=A11,calc!$F$2:$F$10001),0.5)} -> 3.2 | E11: {=_xlfn.STDEV.S(IF(calc!$B$2:$B$10001=A11,calc!$F$2:$F$10001))} -> 1.4322659 | F11: {=_xlfn.PERCENTILE.INC(IF(calc!$B$2:$B$10001=A11,calc!$F$2:$F$10001),0.25)} -> 2.15 | G11: {=_xlfn.PERCENTILE.INC(IF(calc!$B$2:$B$10001=A11,calc!$F$2:$F$10001),0.75)} -> 4.2833333 | H11: {=_xlfn.PERCENTILE.INC(IF(calc!$B$2:$B$10001=A11,calc!$F$2:$F$10001),0.9)} -> 4.9166667 | I11: =_xlfn.MINIFS(calc!$F$2:$F$10001,calc!$B$2:$B$10001,A11) -> 0.75 | J11: =_xlfn.MAXIFS(calc!$F$2:$F$10001,calc!$B$2:$B$10001,A11) -> 7.4833333
A12: Matcha Latte | B12: =COUNTIF(calc!$B$2:$B$10001,A12) -> 482 | C12: =AVERAGEIF(calc!$B$2:$B$10001,A12,calc!$F$2:$F$10001) -> 3.354184 | D12: {=_xlfn.PERCENTILE.INC(IF(calc!$B$2:$B$10001=A12,calc!$F$2:$F$10001),0.5)} -> 3.275 | E12: {=_xlfn.STDEV.S(IF(calc!$B$2:$B$10001=A12,calc!$F$2:$F$10001))} -> 1.4381911 | F12: {=_xlfn.PERCENTILE.INC(IF(calc!$B$2:$B$10001=A12,calc!$F$2:$F$10001),0.25)} -> 2.2 | G12: {=_xlfn.PERCENTILE.INC(IF(calc!$B$2:$B$10001=A12,calc!$F$2:$F$10001),0.75)} -> 4.4666667 | H12: {=_xlfn.PERCENTILE.INC(IF(calc!$B$2:$B$10001=A12,calc!$F$2:$F$10001),0.9)} -> 4.9333333 | I12: =_xlfn.MINIFS(calc!$F$2:$F$10001,calc!$B$2:$B$10001,A12) -> 0.75000001 | J12: =_xlfn.MAXIFS(calc!$F$2:$F$10001,calc!$B$2:$B$10001,A12) -> 7.3666667
A13: Hot Chocolate | B13: =COUNTIF(calc!$B$2:$B$10001,A13) -> 446 | C13: =AVERAGEIF(calc!$B$2:$B$10001,A13,calc!$F$2:$F$10001) -> 3.243722 | D13: {=_xlfn.PERCENTILE.INC(IF(calc!$B$2:$B$10001=A13,calc!$F$2:$F$10001),0.5)} -> 3.1916667 | E13: {=_xlfn.STDEV.S(IF(calc!$B$2:$B$10001=A13,calc!$F$2:$F$10001))} -> 1.4016124 | F13: {=_xlfn.PERCENTILE.INC(IF(calc!$B$2:$B$10001=A13,calc!$F$2:$F$10001),0.25)} -> 2.0666667 | G13: {=_xlfn.PERCENTILE.INC(IF(calc!$B$2:$B$10001=A13,calc!$F$2:$F$10001),0.75)} -> 4.2333333 | H13: {=_xlfn.PERCENTILE.INC(IF(calc!$B$2:$B$10001=A13,calc!$F$2:$F$10001),0.9)} -> 4.9 | I13: =_xlfn.MINIFS(calc!$F$2:$F$10001,calc!$B$2:$B$10001,A13) -> 0.86666667 | J13: =_xlfn.MAXIFS(calc!$F$2:$F$10001,calc!$B$2:$B$10001,A13) -> 7.4333333
A14: OVERALL | B14: =COUNTA(calc!$B$2:$B$10001) -> 10000 | C14: =AVERAGE(calc!$F$2:$F$10001) -> 3.2450583 | D14: =MEDIAN(calc!$F$2:$F$10001) -> 3.1833333 | E14: =_xlfn.STDEV.S(calc!$F$2:$F$10001) -> 1.4314321 | F14: =_xlfn.PERCENTILE.INC(calc!$F$2:$F$10001,0.25) -> 2.0791667 | G14: =_xlfn.PERCENTILE.INC(calc!$F$2:$F$10001,0.75) -> 4.2333333 | H14: =_xlfn.PERCENTILE.INC(calc!$F$2:$F$10001,0.9) -> 4.9166667 | I14: =MIN(calc!$F$2:$F$10001) -> 0.75 | J14: =MAX(calc!$F$2:$F$10001) -> 7.4833333
A16: One-way ANOVA: does mean make_min differ by drink?
A18: Grand mean | B18: =C14 -> 3.2450583
A19: k (groups) | B19: 10
A20: N (total) | B20: =SUM(B4:B13) -> 10000
A21: SS Between | B21: {=SUMPRODUCT(B4:B13,(C4:C13-B18)^2)} -> 16.057743
A22: SS Within | B22: {=SUMPRODUCT(B4:B13-1,E4:E13^2)} -> 20471.872
A23: df Between | B23: =B19-1 -> 9
A24: df Within | B24: =B20-B19 -> 9990
A25: MS Between | B25: =B21/B23 -> 1.7841937
A26: MS Within | B26: =B22/B24 -> 2.0492365
A27: F statistic | B27: =B25/B26 -> 0.87066267
A28: p-value | B28: =_xlfn.F.DIST.RT(B27,B23,B24) -> 0.55079138
A29: Interpretation | B29: =IF(B28<0.05,"Reject H0: at least one drink's mean differs significantly","No significant difference between drinks") -> No significant difference between drinks

Sheet Outliers & Hourly
A1: Outlier detection (IQR method, 1.5×IQR rule)
A3: Metric | B3: Q1 | C3: Q3 | D3: IQR | E3: Lower | F3: Upper | G3: # Outliers | H3: % of total
A4: wait_min | B4: =_xlfn.PERCENTILE.INC(calc!$D$2:$D$10001,0.25) -> 0.88333333 | C4: =_xlfn.PERCENTILE.INC(calc!$D$2:$D$10001,0.75) -> 1.6166667 | D4: =C4-B4 -> 0.73333334 | E4: =B4-1.5*D4 -> -0.21666668 | F4: =C4+1.5*D4 -> 2.7166667 | G4: =COUNTIF(calc!$D$2:$D$10001,">"&F4)+COUNTIF(calc!$D$2:$D$10001,"<"&E4) -> 0 | H4: =G4/10000 -> 0
A5: queue_min | B5: =_xlfn.PERCENTILE.INC(calc!$E$2:$E$10001,0.25) -> 0.5 | C5: =_xlfn.PERCENTILE.INC(calc!$E$2:$E$10001,0.75) -> 1.2833333 | D5: =C5-B5 -> 0.78333333 | E5: =B5-1.5*D5 -> -0.67499999 | F5: =C5+1.5*D5 -> 2.4583333 | G5: =COUNTIF(calc!$E$2:$E$10001,">"&F5)+COUNTIF(calc!$E$2:$E$10001,"<"&E5) -> 470 | H5: =G5/10000 -> 0.047
A6: make_min | B6: =_xlfn.PERCENTILE.INC(calc!$F$2:$F$10001,0.25) -> 2.0791667 | C6: =_xlfn.PERCENTILE.INC(calc!$F$2:$F$10001,0.75) -> 4.2333333 | D6: =C6-B6 -> 2.1541667 | E6: =B6-1.5*D6 -> -1.1520833 | F6: =C6+1.5*D6 -> 7.4645834 | G6: =COUNTIF(calc!$F$2:$F$10001,">"&F6)+COUNTIF(calc!$F$2:$F$10001,"<"&E6) -> 11 | H6: =G6/10000 -> 0.0011
A7: sit_min | B7: =_xlfn.PERCENTILE.INC(calc!$G$2:$G$10001,0.25) -> 5.2666667 | C7: =_xlfn.PERCENTILE.INC(calc!$G$2:$G$10001,0.75) -> 15.1 | D7: =C7-B7 -> 9.8333333 | E7: =B7-1.5*D7 -> -9.4833333 | F7: =C7+1.5*D7 -> 29.85 | G7: =COUNTIF(calc!$G$2:$G$10001,">"&F7)+COUNTIF(calc!$G$2:$G$10001,"<"&E7) -> 0 | H7: =G7/10000 -> 0
A8: total_min | B8: =_xlfn.PERCENTILE.INC(calc!$H$2:$H$10001,0.25) -> 10.683333 | C8: =_xlfn.PERCENTILE.INC(calc!$H$2:$H$10001,0.75) -> 20.633333 | D8: =C8-B8 -> 9.95 | E8: =B8-1.5*D8 -> -4.2416667 | F8: =C8+1.5*D8 -> 35.558333 | G8: =COUNTIF(calc!$H$2:$H$10001,">"&F8)+COUNTIF(calc!$H$2:$H$10001,"<"&E8) -> 0 | H8: =G8/10000 -> 0
A11: Hour-of-day trend
A13: Hour | B13: Orders | C13: Avg wait | D13: Avg queue | E13: Avg make | F13: Avg sit | G13: Avg total
A15: 7 | B15: =COUNTIF(calc!$I$2:$I$10001,A15) -> 1014 | C15: =IFERROR(AVERAGEIF(calc!$I$2:$I$10001,A15,calc!$D$2:$D$10001),"") -> 1.2278928 | D15: =IFERROR(AVERAGEIF(calc!$I$2:$I$10001,A15,calc!$E$2:$E$10001),"") -> 0.98221565 | E15: =IFERROR(AVERAGEIF(calc!$I$2:$I$10001,A15,calc!$F$2:$F$10001),"") -> 3.2264793 | F15: =IFERROR(AVERAGEIF(calc!$I$2:$I$10001,A15,calc!$G$2:$G$10001),"") -> 10.031197 | G15: =IFERROR(AVERAGEIF(calc!$I$2:$I$10001,A15,calc!$H$2:$H$10001),"") -> 15.467784
A16: 8 | B16: =COUNTIF(calc!$I$2:$I$10001,A16) -> 1004 | C16: =IFERROR(AVERAGEIF(calc!$I$2:$I$10001,A16,calc!$D$2:$D$10001),"") -> 1.2552623 | D16: =IFERROR(AVERAGEIF(calc!$I$2:$I$10001,A16,calc!$E$2:$E$10001),"") -> 0.98512616 | E16: =IFERROR(AVERAGEIF(calc!$I$2:$I$10001,A16,calc!$F$2:$F$10001),"") -> 3.2380312 | F16: =IFERROR(AVERAGEIF(calc!$I$2:$I$10001,A16,calc!$G$2:$G$10001),"") -> 10.401959 | G16: =IFERROR(AVERAGEIF(calc!$I$2:$I$10001,A16,calc!$H$2:$H$10001),"") -> 15.880378
A17: 9 | B17: =COUNTIF(calc!$I$2:$I$10001,A17) -> 976 | C17: =IFERROR(AVERAGEIF(calc!$I$2:$I$10001,A17,calc!$D$2:$D$10001),"") -> 1.207599 | D17: =IFERROR(AVERAGEIF(calc!$I$2:$I$10001,A17,calc!$E$2:$E$10001),"") -> 0.98119877 | E17: =IFERROR(AVERAGEIF(calc!$I$2:$I$10001,A17,calc!$F$2:$F$10001),"") -> 3.2289617 | F17: =IFERROR(AVERAGEIF(calc!$I$2:$I$10001,A17,calc!$G$2:$G$10001),"") -> 10.176383 | G17: =IFERROR(AVERAGEIF(calc!$I$2:$I$10001,A17,calc!$H$2:$H$10001),"") -> 15.594143
A18: 10 | B18: =COUNTIF(calc!$I$2:$I$10001,A18) -> 982 | C18: =IFERROR(AVERAGEIF(calc!$I$2:$I$10001,A18,calc!$D$2:$D$10001),"") -> 1.2387135 | D18: =IFERROR(AVERAGEIF(calc!$I$2:$I$10001,A18,calc!$E$2:$E$10001),"") -> 0.96858452 | E18: =IFERROR(AVERAGEIF(calc!$I$2:$I$10001,A18,calc!$F$2:$F$10001),"") -> 3.2756619 | F18: =IFERROR(AVERAGEIF(calc!$I$2:$I$10001,A18,calc!$G$2:$G$10001),"") -> 10.346775 | G18: =IFERROR(AVERAGEIF(calc!$I$2:$I$10001,A18,calc!$H$2:$H$10001),"") -> 15.829735
A19: 11 | B19: =COUNTIF(calc!$I$2:$I$10001,A19) -> 958 | C19: =IFERROR(AVERAGEIF(calc!$I$2:$I$10001,A19,calc!$D$2:$D$10001),"") -> 1.2466597 | D19: =IFERROR(AVERAGEIF(calc!$I$2:$I$10001,A19,calc!$E$2:$E$10001),"") -> 0.97792276 | E19: =IFERROR(AVERAGEIF(calc!$I$2:$I$10001,A19,calc!$F$2:$F$10001),"") -> 3.2484342 | F19: =IFERROR(AVERAGEIF(calc!$I$2:$I$10001,A19,calc!$G$2:$G$10001),"") -> 10.466719 | G19: =IFERROR(AVERAGEIF(calc!$I$2:$I$10001,A19,calc!$H$2:$H$10001),"") -> 15.939736
A20: 12 | B20: =COUNTIF(calc!$I$2:$I$10001,A20) -> 963 | C20: =IFERROR(AVERAGEIF(calc!$I$2:$I$10001,A20,calc!$D$2:$D$10001),"") -> 1.2295777 | D20: =IFERROR(AVERAGEIF(calc!$I$2:$I$10001,A20,calc!$E$2:$E$10001),"") -> 0.96623399 | E20: =IFERROR(AVERAGEIF(calc!$I$2:$I$10001,A20,calc!$F$2:$F$10001),"") -> 3.2361544 | F20: =IFERROR(AVERAGEIF(calc!$I$2:$I$10001,A20,calc!$G$2:$G$10001),"") -> 10.000208 | G20: =IFERROR(AVERAGEIF(calc!$I$2:$I$10001,A20,calc!$H$2:$H$10001),"") -> 15.432174
A21: 13 | B21: =COUNTIF(calc!$I$2:$I$10001,A21) -> 1026 | C21: =IFERROR(AVERAGEIF(calc!$I$2:$I$10001,A21,calc!$D$2:$D$10001),"") -> 1.2761046 | D21: =IFERROR(AVERAGEIF(calc!$I$2:$I$10001,A21,calc!$E$2:$E$10001),"") -> 0.94423327 | E21: =IFERROR(AVERAGEIF(calc!$I$2:$I$10001,A21,calc!$F$2:$F$10001),"") -> 3.1649448 | F21: =IFERROR(AVERAGEIF(calc!$I$2:$I$10001,A21,calc!$G$2:$G$10001),"") -> 10.221849 | G21: =IFERROR(AVERAGEIF(calc!$I$2:$I$10001,A21,calc!$H$2:$H$10001),"") -> 15.607131
A22: 14 | B22: =COUNTIF(calc!$I$2:$I$10001,A22) -> 1024 | C22: =IFERROR(AVERAGEIF(calc!$I$2:$I$10001,A22,calc!$D$2:$D$10001),"") -> 1.2562663 | D22: =IFERROR(AVERAGEIF(calc!$I$2:$I$10001,A22,calc!$E$2:$E$10001),"") -> 0.97988281 | E22: =IFERROR(AVERAGEIF(calc!$I$2:$I$10001,A22,calc!$F$2:$F$10001),"") -> 3.3868327 | F22: =IFERROR(AVERAGEIF(calc!$I$2:$I$10001,A22,calc!$G$2:$G$10001),"") -> 10.260628 | G22: =IFERROR(AVERAGEIF(calc!$I$2:$I$10001,A22,calc!$H$2:$H$10001),"") -> 15.88361
A23: 15 | B23: =COUNTIF(calc!$I$2:$I$10001,A23) -> 1062 | C23: =IFERROR(AVERAGEIF(calc!$I$2:$I$10001,A23,calc!$D$2:$D$10001),"") -> 1.2352323 | D23: =IFERROR(AVERAGEIF(calc!$I$2:$I$10001,A23,calc!$E$2:$E$10001),"") -> 1.0086943 | E23: =IFERROR(AVERAGEIF(calc!$I$2:$I$10001,A23,calc!$F$2:$F$10001),"") -> 3.2639987 | F23: =IFERROR(AVERAGEIF(calc!$I$2:$I$10001,A23,calc!$G$2:$G$10001),"") -> 9.9000157 | G23: =IFERROR(AVERAGEIF(calc!$I$2:$I$10001,A23,calc!$H$2:$H$10001),"") -> 15.407941
A24: 16 | B24: =COUNTIF(calc!$I$2:$I$10001,A24) -> 991 | C24: =IFERROR(AVERAGEIF(calc!$I$2:$I$10001,A24,calc!$D$2:$D$10001),"") -> 1.2584763 | D24: =IFERROR(AVERAGEIF(calc!$I$2:$I$10001,A24,calc!$E$2:$E$10001),"") -> 0.95401951 | E24: =IFERROR(AVERAGEIF(calc!$I$2:$I$10001,A24,calc!$F$2:$F$10001),"") -> 3.1782543 | F24: =IFERROR(AVERAGEIF(calc!$I$2:$I$10001,A24,calc!$G$2:$G$10001),"") -> 10.083317 | G24: =IFERROR(AVERAGEIF(calc!$I$2:$I$10001,A24,calc!$H$2:$H$10001),"") -> 15.474067

Sheet Flagged Orders
A1: Flagged Orders Analysis
A2: Three independent failure modes identified across 10,000 orders. Bounds: queue_min > 2.458, make_min > 7.465, order_sent_back = 1.
A4: Overview
A5: Total orders | B5: =COUNTA(in!A2:A10001) -> 10000
A6: Queue outliers (queue_min > 2.458) | B6: =COUNTIF(calc!E2:E10001,">2.458") -> 470 | C6: =B6/B5 -> 0.047
A7: Make outliers (make_min > 7.465) | B7: =COUNTIF(calc!F2:F10001,">7.465") -> 11 | C7: =B7/B5 -> 0.0011
A8: Sent-back orders | B8: =COUNTIF(in!D2:D10001,1) -> 120 | C8: =B8/B5 -> 0.012
A9: Any flag (union) | B9: {=SUMPRODUCT(--((calc!E2:E10001>2.458)+(calc!F2:F10001>7.465)+(in!D2:D10001=1)>0))} -> 594 | C9: =B9/B5 -> 0.0594
A11: Failure mode 1: Queue outliers by agent
A12: Agent | B12: Total orders | C12: Queue outliers | D12: Rate | E12: Share of outliers
A13: Alice | B13: =COUNTIF(calc!C2:C10001,A13) -> 2503 | C13: =COUNTIFS(calc!C2:C10001,A13,calc!E2:E10001,">2.458") -> 0 | D13: =IFERROR(C13/B13,0) -> 0 | E13: =IFERROR(C13/$B$6,0) -> 0
A14: Bob | B14: =COUNTIF(calc!C2:C10001,A14) -> 2456 | C14: =COUNTIFS(calc!C2:C10001,A14,calc!E2:E10001,">2.458") -> 0 | D14: =IFERROR(C14/B14,0) -> 0 | E14: =IFERROR(C14/$B$6,0) -> 0
A15: Charlie | B15: =COUNTIF(calc!C2:C10001,A15) -> 2002 | C15: =COUNTIFS(calc!C2:C10001,A15,calc!E2:E10001,">2.458") -> 470 | D15: =IFERROR(C15/B15,0) -> 0.23476523 | E15: =IFERROR(C15/$B$6,0) -> 1
A16: David | B16: =COUNTIF(calc!C2:C10001,A16) -> 1514 | C16: =COUNTIFS(calc!C2:C10001,A16,calc!E2:E10001,">2.458") -> 0 | D16: =IFERROR(C16/B16,0) -> 0 | E16: =IFERROR(C16/$B$6,0) -> 0
A17: Eve | B17: =COUNTIF(calc!C2:C10001,A17) -> 1525 | C17: =COUNTIFS(calc!C2:C10001,A17,calc!E2:E10001,">2.458") -> 0 | D17: =IFERROR(C17/B17,0) -> 0 | E17: =IFERROR(C17/$B$6,0) -> 0
A19: Failure mode 2: Make outliers by agent
A20: Agent | B20: Total orders | C20: Make outliers | D20: Rate | E20: Share of outliers
A21: Alice | B21: =COUNTIF(calc!C2:C10001,A21) -> 2503 | C21: =COUNTIFS(calc!C2:C10001,A21,calc!F2:F10001,">7.465") -> 0 | D21: =IFERROR(C21/B21,0) -> 0 | E21: =IFERROR(C21/$B$7,0) -> 0
A22: Bob | B22: =COUNTIF(calc!C2:C10001,A22) -> 2456 | C22: =COUNTIFS(calc!C2:C10001,A22,calc!F2:F10001,">7.465") -> 0 | D22: =IFERROR(C22/B22,0) -> 0 | E22: =IFERROR(C22/$B$7,0) -> 0
A23: Charlie | B23: =COUNTIF(calc!C2:C10001,A23) -> 2002 | C23: =COUNTIFS(calc!C2:C10001,A23,calc!F2:F10001,">7.465") -> 11 | D23: =IFERROR(C23/B23,0) -> 0.0054945055 | E23: =IFERROR(C23/$B$7,0) -> 1
A24: David | B24: =COUNTIF(calc!C2:C10001,A24) -> 1514 | C24: =COUNTIFS(calc!C2:C10001,A24,calc!F2:F10001,">7.465") -> 0 | D24: =IFERROR(C24/B24,0) -> 0 | E24: =IFERROR(C24/$B$7,0) -> 0
A25: Eve | B25: =COUNTIF(calc!C2:C10001,A25) -> 1525 | C25: =COUNTIFS(calc!C2:C10001,A25,calc!F2:F10001,">7.465") -> 0 | D25: =IFERROR(C25/B25,0) -> 0 | E25: =IFERROR(C25/$B$7,0) -> 0
A27: Failure mode 3: Sent-back orders by drink
A28: Drink | B28: Total orders | C28: Sent back | D28: Rate | E28: Share of sent-backs
A29: Latte | B29: =COUNTIF(in!B2:B10001,A29) -> 2481 | C29: =COUNTIFS(in!B2:B10001,A29,in!D2:D10001,1) -> 15 | D29: =IFERROR(C29/B29,0) -> 0.0060459492 | E29: =IFERROR(C29/$B$8,0) -> 0.125
A30: Cappuccino | B30: =COUNTIF(in!B2:B10001,A30) -> 1466 | C30: =COUNTIFS(in!B2:B10001,A30,in!D2:D10001,1) -> 15 | D30: =IFERROR(C30/B30,0) -> 0.010231924 | E30: =IFERROR(C30/$B$8,0) -> 0.125
A31: Espresso | B31: =COUNTIF(in!B2:B10001,A31) -> 1031 | C31: =COUNTIFS(in!B2:B10001,A31,in!D2:D10001,1) -> 7 | D31: =IFERROR(C31/B31,0) -> 0.0067895247 | E31: =IFERROR(C31/$B$8,0) -> 0.058333333
A32: Cold Brew | B32: =COUNTIF(in!B2:B10001,A32) -> 980 | C32: =COUNTIFS(in!B2:B10001,A32,in!D2:D10001,1) -> 6 | D32: =IFERROR(C32/B32,0) -> 0.006122449 | E32: =IFERROR(C32/$B$8,0) -> 0.05
A33: Americano | B33: =COUNTIF(in!B2:B10001,A33) -> 978 | C33: =COUNTIFS(in!B2:B10001,A33,in!D2:D10001,1) -> 7 | D33: =IFERROR(C33/B33,0) -> 0.0071574642 | E33: =IFERROR(C33/$B$8,0) -> 0.058333333
A34: Mocha | B34: =COUNTIF(in!B2:B10001,A34) -> 804 | C34: =COUNTIFS(in!B2:B10001,A34,in!D2:D10001,1) -> 8 | D34: =IFERROR(C34/B34,0) -> 0.0099502488 | E34: =IFERROR(C34/$B$8,0) -> 0.066666667
A35: Flat White | B35: =COUNTIF(in!B2:B10001,A35) -> 716 | C35: =COUNTIFS(in!B2:B10001,A35,in!D2:D10001,1) -> 5 | D35: =IFERROR(C35/B35,0) -> 0.0069832402 | E35: =IFERROR(C35/$B$8,0) -> 0.041666667
A36: Tea | B36: =COUNTIF(in!B2:B10001,A36) -> 616 | C36: =COUNTIFS(in!B2:B10001,A36,in!D2:D10001,1) -> 3 | D36: =IFERROR(C36/B36,0) -> 0.0048701299 | E36: =IFERROR(C36/$B$8,0) -> 0.025
A37: Matcha Latte | B37: =COUNTIF(in!B2:B10001,A37) -> 482 | C37: =COUNTIFS(in!B2:B10001,A37,in!D2:D10001,1) -> 51 | D37: =IFERROR(C37/B37,0) -> 0.10580913 | E37: =IFERROR(C37/$B$8,0) -> 0.425
A38: Hot Chocolate | B38: =COUNTIF(in!B2:B10001,A38) -> 446 | C38: =COUNTIFS(in!B2:B10001,A38,in!D2:D10001,1) -> 3 | D38: =IFERROR(C38/B38,0) -> 0.0067264574 | E38: =IFERROR(C38/$B$8,0) -> 0.025
A40: Sent-back orders by agent (control: agents are uniform)
A41: Agent | B41: Total orders | C41: Sent back | D41: Rate
A42: Alice | B42: =COUNTIF(in!C2:C10001,A42) -> 2503 | C42: =COUNTIFS(in!C2:C10001,A42,in!D2:D10001,1) -> 33 | D42: =IFERROR(C42/B42,0) -> 0.013184179
A43: Bob | B43: =COUNTIF(in!C2:C10001,A43) -> 2456 | C43: =COUNTIFS(in!C2:C10001,A43,in!D2:D10001,1) -> 29 | D43: =IFERROR(C43/B43,0) -> 0.011807818
A44: Charlie | B44: =COUNTIF(in!C2:C10001,A44) -> 2002 | C44: =COUNTIFS(in!C2:C10001,A44,in!D2:D10001,1) -> 22 | D44: =IFERROR(C44/B44,0) -> 0.010989011
A45: David | B45: =COUNTIF(in!C2:C10001,A45) -> 1514 | C45: =COUNTIFS(in!C2:C10001,A45,in!D2:D10001,1) -> 13 | D45: =IFERROR(C45/B45,0) -> 0.0085865258
...

Sheet Sheet2
A1: Flag | B1: Concentration | C1: Lift
A2: Queue outliers (470) | B2: 100% Charlie (23.5% of his orders) | C2: Rest of staff = 0%
A3: Make outliers (11) | B3: 100% Charlie | C3: Same agent issue
A4: Sent-back (120) | B4: 88% Matcha Lattes (10.6% defect rate vs ~0.7% baseline) | C4: 15× the baseline

Sheet Notes
A1: The p-value column uses an F-distribution approximation in Excel since there's no native studentized-range function; the four "YES" rows are effectively p ≈ 0 either way. I verified all p-values against scipy's exact studentized-range CDF.
A2: Charlie's std-dev (1.97) is also ~70% larger than the others (~1.14), so it's both higher mean and higher variability — Tukey assumes equal variances, so the Charlie comparisons are technically on shakier ground, but the effect size is so large (40+ standard errors) that it's robust to that.
A3: Charlie causes queue and make outliers. 100% of the 470 queue outliers and all 11 make outliers are Charlie. 23.5% of his orders queue too long. This is the same pattern Tukey HSD already flagged — it's a workload/skill issue, not a recipe issue.
A4: Matcha Latte causes sent-back orders. Matcha sent-back rate is 10.58% (51 of 482), vs 0.5–1.0% for every other drink. Matcha accounts for 42.5% of all sent-backs despite being only 4.8% of volume. This is a recipe/process issue, not an agent issue — sent-back rates are roughly uniform across agents (0.86–1.51%).
A5: The two problems are nearly disjoint (~0% overlap between Charlie's slow orders and the Matcha returns), so they need separate interventions: retraining/workload audit or rebalancing for Charlie, and a recipe/process/training audit for Matcha Latte.
